nohup: ignoring input
2025-07-11 22:56:25.161 
Warning: the config option 'server.enableCORS=false' is not compatible with
'server.enableXsrfProtection=true'.
As a result, 'server.enableCORS' is being overridden to 'true'.

More information:
In order to protect against CSRF attacks, we send a cookie with each request.
To do so, we must specify allowable origins, which places a restriction on
cross-origin resource sharing.

If cross origin resource sharing is required, please disable server.enableXsrfProtection.
            

Collecting usage statistics. To deactivate, set browser.gatherUsageStats to false.


  You can now view your Streamlit app in your browser.

  URL: http://0.0.0.0:4006

Task exception was never retrieved
future: <Task finished name='Task-20669' coro=<WebSocketProtocol13.write_message.<locals>.wrapper() done, defined at /home/pscadmin/.local/lib/python3.10/site-packages/tornado/websocket.py:1111> exception=WebSocketClosedError()>
Traceback (most recent call last):
  File "/home/pscadmin/.local/lib/python3.10/site-packages/tornado/websocket.py", line 1113, in wrapper
    await fut
tornado.iostream.StreamClosedError: Stream is closed

During handling of the above exception, another exception occurred:

Traceback (most recent call last):
  File "/home/pscadmin/.local/lib/python3.10/site-packages/tornado/websocket.py", line 1115, in wrapper
    raise WebSocketClosedError()
tornado.websocket.WebSocketClosedError
Task exception was never retrieved
future: <Task finished name='Task-20670' coro=<WebSocketProtocol13.write_message.<locals>.wrapper() done, defined at /home/pscadmin/.local/lib/python3.10/site-packages/tornado/websocket.py:1111> exception=WebSocketClosedError()>
Traceback (most recent call last):
  File "/home/pscadmin/.local/lib/python3.10/site-packages/tornado/websocket.py", line 1113, in wrapper
    await fut
tornado.iostream.StreamClosedError: Stream is closed

During handling of the above exception, another exception occurred:

Traceback (most recent call last):
  File "/home/pscadmin/.local/lib/python3.10/site-packages/tornado/websocket.py", line 1115, in wrapper
    raise WebSocketClosedError()
tornado.websocket.WebSocketClosedError
Task exception was never retrieved
future: <Task finished name='Task-20671' coro=<WebSocketProtocol13.write_message.<locals>.wrapper() done, defined at /home/pscadmin/.local/lib/python3.10/site-packages/tornado/websocket.py:1111> exception=WebSocketClosedError()>
Traceback (most recent call last):
  File "/home/pscadmin/.local/lib/python3.10/site-packages/tornado/websocket.py", line 1113, in wrapper
    await fut
tornado.iostream.StreamClosedError: Stream is closed

During handling of the above exception, another exception occurred:

Traceback (most recent call last):
  File "/home/pscadmin/.local/lib/python3.10/site-packages/tornado/websocket.py", line 1115, in wrapper
    raise WebSocketClosedError()
tornado.websocket.WebSocketClosedError
Task exception was never retrieved
future: <Task finished name='Task-20672' coro=<WebSocketProtocol13.write_message.<locals>.wrapper() done, defined at /home/pscadmin/.local/lib/python3.10/site-packages/tornado/websocket.py:1111> exception=WebSocketClosedError()>
Traceback (most recent call last):
  File "/home/pscadmin/.local/lib/python3.10/site-packages/tornado/websocket.py", line 1113, in wrapper
    await fut
tornado.iostream.StreamClosedError: Stream is closed

During handling of the above exception, another exception occurred:

Traceback (most recent call last):
  File "/home/pscadmin/.local/lib/python3.10/site-packages/tornado/websocket.py", line 1115, in wrapper
    raise WebSocketClosedError()
tornado.websocket.WebSocketClosedError
Task exception was never retrieved
future: <Task finished name='Task-20675' coro=<WebSocketProtocol13.write_message.<locals>.wrapper() done, defined at /home/pscadmin/.local/lib/python3.10/site-packages/tornado/websocket.py:1111> exception=WebSocketClosedError()>
Traceback (most recent call last):
  File "/home/pscadmin/.local/lib/python3.10/site-packages/tornado/websocket.py", line 1113, in wrapper
    await fut
tornado.iostream.StreamClosedError: Stream is closed

During handling of the above exception, another exception occurred:

Traceback (most recent call last):
  File "/home/pscadmin/.local/lib/python3.10/site-packages/tornado/websocket.py", line 1115, in wrapper
    raise WebSocketClosedError()
tornado.websocket.WebSocketClosedError
Task exception was never retrieved
future: <Task finished name='Task-20676' coro=<WebSocketProtocol13.write_message.<locals>.wrapper() done, defined at /home/pscadmin/.local/lib/python3.10/site-packages/tornado/websocket.py:1111> exception=WebSocketClosedError()>
Traceback (most recent call last):
  File "/home/pscadmin/.local/lib/python3.10/site-packages/tornado/websocket.py", line 1113, in wrapper
    await fut
tornado.iostream.StreamClosedError: Stream is closed

During handling of the above exception, another exception occurred:

Traceback (most recent call last):
  File "/home/pscadmin/.local/lib/python3.10/site-packages/tornado/websocket.py", line 1115, in wrapper
    raise WebSocketClosedError()
tornado.websocket.WebSocketClosedError
Task exception was never retrieved
future: <Task finished name='Task-20677' coro=<WebSocketProtocol13.write_message.<locals>.wrapper() done, defined at /home/pscadmin/.local/lib/python3.10/site-packages/tornado/websocket.py:1111> exception=WebSocketClosedError()>
Traceback (most recent call last):
  File "/home/pscadmin/.local/lib/python3.10/site-packages/tornado/websocket.py", line 1113, in wrapper
    await fut
tornado.iostream.StreamClosedError: Stream is closed

During handling of the above exception, another exception occurred:

Traceback (most recent call last):
  File "/home/pscadmin/.local/lib/python3.10/site-packages/tornado/websocket.py", line 1115, in wrapper
    raise WebSocketClosedError()
tornado.websocket.WebSocketClosedError
Task exception was never retrieved
future: <Task finished name='Task-20678' coro=<WebSocketProtocol13.write_message.<locals>.wrapper() done, defined at /home/pscadmin/.local/lib/python3.10/site-packages/tornado/websocket.py:1111> exception=WebSocketClosedError()>
Traceback (most recent call last):
  File "/home/pscadmin/.local/lib/python3.10/site-packages/tornado/websocket.py", line 1113, in wrapper
    await fut
tornado.iostream.StreamClosedError: Stream is closed

During handling of the above exception, another exception occurred:

Traceback (most recent call last):
  File "/home/pscadmin/.local/lib/python3.10/site-packages/tornado/websocket.py", line 1115, in wrapper
    raise WebSocketClosedError()
tornado.websocket.WebSocketClosedError
2025-07-14 21:40:31.885 Uncaught app execution
Traceback (most recent call last):
  File "/home/pscadmin/.local/lib/python3.10/site-packages/pandas/io/sql.py", line 2664, in execute
    cur.execute(sql, *args)
sqlite3.OperationalError: no such table: shop_location_reconciled

The above exception was the direct cause of the following exception:

Traceback (most recent call last):
  File "/home/pscadmin/.local/lib/python3.10/site-packages/streamlit/runtime/scriptrunner/exec_code.py", line 128, in exec_func_with_error_handling
    result = func()
  File "/home/pscadmin/.local/lib/python3.10/site-packages/streamlit/runtime/scriptrunner/script_runner.py", line 669, in code_to_exec
    exec(code, module.__dict__)  # noqa: S102
  File "/home/pscadmin/recon/app_by_day.py", line 79, in <module>
    df = load_daily_data()
  File "/home/pscadmin/.local/lib/python3.10/site-packages/streamlit/runtime/caching/cache_utils.py", line 219, in __call__
    return self._get_or_create_cached_value(args, kwargs, spinner_message)
  File "/home/pscadmin/.local/lib/python3.10/site-packages/streamlit/runtime/caching/cache_utils.py", line 261, in _get_or_create_cached_value
    return self._handle_cache_miss(cache, value_key, func_args, func_kwargs)
  File "/home/pscadmin/.local/lib/python3.10/site-packages/streamlit/runtime/caching/cache_utils.py", line 320, in _handle_cache_miss
    computed_value = self._info.func(*func_args, **func_kwargs)
  File "/home/pscadmin/recon/app_by_day.py", line 19, in load_daily_data
    df = pd.read_sql_query(
  File "/home/pscadmin/.local/lib/python3.10/site-packages/pandas/io/sql.py", line 528, in read_sql_query
    return pandas_sql.read_query(
  File "/home/pscadmin/.local/lib/python3.10/site-packages/pandas/io/sql.py", line 2728, in read_query
    cursor = self.execute(sql, params)
  File "/home/pscadmin/.local/lib/python3.10/site-packages/pandas/io/sql.py", line 2676, in execute
    raise ex from exc
pandas.errors.DatabaseError: Execution failed on sql 'SELECT * FROM shop_location_reconciled WHERE is_gwp_line IS NULL OR is_gwp_line != 1': no such table: shop_location_reconciled
2025-07-14 21:40:46.728 Uncaught app execution
Traceback (most recent call last):
  File "/home/pscadmin/.local/lib/python3.10/site-packages/pandas/io/sql.py", line 2664, in execute
    cur.execute(sql, *args)
sqlite3.OperationalError: no such table: shop_location_reconciled

The above exception was the direct cause of the following exception:

Traceback (most recent call last):
  File "/home/pscadmin/.local/lib/python3.10/site-packages/streamlit/runtime/scriptrunner/exec_code.py", line 128, in exec_func_with_error_handling
    result = func()
  File "/home/pscadmin/.local/lib/python3.10/site-packages/streamlit/runtime/scriptrunner/script_runner.py", line 669, in code_to_exec
    exec(code, module.__dict__)  # noqa: S102
  File "/home/pscadmin/recon/app_by_day.py", line 79, in <module>
    df = load_daily_data()
  File "/home/pscadmin/.local/lib/python3.10/site-packages/streamlit/runtime/caching/cache_utils.py", line 219, in __call__
    return self._get_or_create_cached_value(args, kwargs, spinner_message)
  File "/home/pscadmin/.local/lib/python3.10/site-packages/streamlit/runtime/caching/cache_utils.py", line 261, in _get_or_create_cached_value
    return self._handle_cache_miss(cache, value_key, func_args, func_kwargs)
  File "/home/pscadmin/.local/lib/python3.10/site-packages/streamlit/runtime/caching/cache_utils.py", line 320, in _handle_cache_miss
    computed_value = self._info.func(*func_args, **func_kwargs)
  File "/home/pscadmin/recon/app_by_day.py", line 19, in load_daily_data
    df = pd.read_sql_query(
  File "/home/pscadmin/.local/lib/python3.10/site-packages/pandas/io/sql.py", line 528, in read_sql_query
    return pandas_sql.read_query(
  File "/home/pscadmin/.local/lib/python3.10/site-packages/pandas/io/sql.py", line 2728, in read_query
    cursor = self.execute(sql, params)
  File "/home/pscadmin/.local/lib/python3.10/site-packages/pandas/io/sql.py", line 2676, in execute
    raise ex from exc
pandas.errors.DatabaseError: Execution failed on sql 'SELECT * FROM shop_location_reconciled WHERE is_gwp_line IS NULL OR is_gwp_line != 1': no such table: shop_location_reconciled
2025-07-14 21:41:09.992 Uncaught app execution
Traceback (most recent call last):
  File "/home/pscadmin/.local/lib/python3.10/site-packages/pandas/io/sql.py", line 2664, in execute
    cur.execute(sql, *args)
sqlite3.OperationalError: no such table: shop_location_reconciled

The above exception was the direct cause of the following exception:

Traceback (most recent call last):
  File "/home/pscadmin/.local/lib/python3.10/site-packages/streamlit/runtime/scriptrunner/exec_code.py", line 128, in exec_func_with_error_handling
    result = func()
  File "/home/pscadmin/.local/lib/python3.10/site-packages/streamlit/runtime/scriptrunner/script_runner.py", line 669, in code_to_exec
    exec(code, module.__dict__)  # noqa: S102
  File "/home/pscadmin/recon/app_by_day.py", line 79, in <module>
    df = load_daily_data()
  File "/home/pscadmin/.local/lib/python3.10/site-packages/streamlit/runtime/caching/cache_utils.py", line 219, in __call__
    return self._get_or_create_cached_value(args, kwargs, spinner_message)
  File "/home/pscadmin/.local/lib/python3.10/site-packages/streamlit/runtime/caching/cache_utils.py", line 261, in _get_or_create_cached_value
    return self._handle_cache_miss(cache, value_key, func_args, func_kwargs)
  File "/home/pscadmin/.local/lib/python3.10/site-packages/streamlit/runtime/caching/cache_utils.py", line 320, in _handle_cache_miss
    computed_value = self._info.func(*func_args, **func_kwargs)
  File "/home/pscadmin/recon/app_by_day.py", line 19, in load_daily_data
    df = pd.read_sql_query(
  File "/home/pscadmin/.local/lib/python3.10/site-packages/pandas/io/sql.py", line 528, in read_sql_query
    return pandas_sql.read_query(
  File "/home/pscadmin/.local/lib/python3.10/site-packages/pandas/io/sql.py", line 2728, in read_query
    cursor = self.execute(sql, params)
  File "/home/pscadmin/.local/lib/python3.10/site-packages/pandas/io/sql.py", line 2676, in execute
    raise ex from exc
pandas.errors.DatabaseError: Execution failed on sql 'SELECT * FROM shop_location_reconciled WHERE is_gwp_line IS NULL OR is_gwp_line != 1': no such table: shop_location_reconciled
2025-07-14 21:41:12.420 Uncaught app execution
Traceback (most recent call last):
  File "/home/pscadmin/.local/lib/python3.10/site-packages/pandas/io/sql.py", line 2664, in execute
    cur.execute(sql, *args)
sqlite3.OperationalError: no such table: shop_location_reconciled

The above exception was the direct cause of the following exception:

Traceback (most recent call last):
  File "/home/pscadmin/.local/lib/python3.10/site-packages/streamlit/runtime/scriptrunner/exec_code.py", line 128, in exec_func_with_error_handling
    result = func()
  File "/home/pscadmin/.local/lib/python3.10/site-packages/streamlit/runtime/scriptrunner/script_runner.py", line 669, in code_to_exec
    exec(code, module.__dict__)  # noqa: S102
  File "/home/pscadmin/recon/app_by_day.py", line 79, in <module>
    df = load_daily_data()
  File "/home/pscadmin/.local/lib/python3.10/site-packages/streamlit/runtime/caching/cache_utils.py", line 219, in __call__
    return self._get_or_create_cached_value(args, kwargs, spinner_message)
  File "/home/pscadmin/.local/lib/python3.10/site-packages/streamlit/runtime/caching/cache_utils.py", line 261, in _get_or_create_cached_value
    return self._handle_cache_miss(cache, value_key, func_args, func_kwargs)
  File "/home/pscadmin/.local/lib/python3.10/site-packages/streamlit/runtime/caching/cache_utils.py", line 320, in _handle_cache_miss
    computed_value = self._info.func(*func_args, **func_kwargs)
  File "/home/pscadmin/recon/app_by_day.py", line 19, in load_daily_data
    df = pd.read_sql_query(
  File "/home/pscadmin/.local/lib/python3.10/site-packages/pandas/io/sql.py", line 528, in read_sql_query
    return pandas_sql.read_query(
  File "/home/pscadmin/.local/lib/python3.10/site-packages/pandas/io/sql.py", line 2728, in read_query
    cursor = self.execute(sql, params)
  File "/home/pscadmin/.local/lib/python3.10/site-packages/pandas/io/sql.py", line 2676, in execute
    raise ex from exc
pandas.errors.DatabaseError: Execution failed on sql 'SELECT * FROM shop_location_reconciled WHERE is_gwp_line IS NULL OR is_gwp_line != 1': no such table: shop_location_reconciled
2025-07-15 01:19:01.230 Uncaught app execution
Traceback (most recent call last):
  File "/home/pscadmin/.local/lib/python3.10/site-packages/pandas/io/sql.py", line 2664, in execute
    cur.execute(sql, *args)
sqlite3.OperationalError: no such table: shop_location_reconciled

The above exception was the direct cause of the following exception:

Traceback (most recent call last):
  File "/home/pscadmin/.local/lib/python3.10/site-packages/streamlit/runtime/scriptrunner/exec_code.py", line 128, in exec_func_with_error_handling
    result = func()
  File "/home/pscadmin/.local/lib/python3.10/site-packages/streamlit/runtime/scriptrunner/script_runner.py", line 669, in code_to_exec
    exec(code, module.__dict__)  # noqa: S102
  File "/home/pscadmin/recon/app_by_day.py", line 79, in <module>
    df = load_daily_data()
  File "/home/pscadmin/.local/lib/python3.10/site-packages/streamlit/runtime/caching/cache_utils.py", line 219, in __call__
    return self._get_or_create_cached_value(args, kwargs, spinner_message)
  File "/home/pscadmin/.local/lib/python3.10/site-packages/streamlit/runtime/caching/cache_utils.py", line 261, in _get_or_create_cached_value
    return self._handle_cache_miss(cache, value_key, func_args, func_kwargs)
  File "/home/pscadmin/.local/lib/python3.10/site-packages/streamlit/runtime/caching/cache_utils.py", line 320, in _handle_cache_miss
    computed_value = self._info.func(*func_args, **func_kwargs)
  File "/home/pscadmin/recon/app_by_day.py", line 19, in load_daily_data
    df = pd.read_sql_query(
  File "/home/pscadmin/.local/lib/python3.10/site-packages/pandas/io/sql.py", line 528, in read_sql_query
    return pandas_sql.read_query(
  File "/home/pscadmin/.local/lib/python3.10/site-packages/pandas/io/sql.py", line 2728, in read_query
    cursor = self.execute(sql, params)
  File "/home/pscadmin/.local/lib/python3.10/site-packages/pandas/io/sql.py", line 2676, in execute
    raise ex from exc
pandas.errors.DatabaseError: Execution failed on sql 'SELECT * FROM shop_location_reconciled WHERE is_gwp_line IS NULL OR is_gwp_line != 1': no such table: shop_location_reconciled
